/data/miniforge3/lib/python3.10/site-packages/transformers/utils/hub.py:111: FutureWarning: Using `TRANSFORMERS_CACHE` is deprecated and will be removed in v5 of Transformers. Use `HF_HOME` instead.
  warnings.warn(
Loading ARC dataset...
Loaded 10 train problems
Loaded 5 eval problems
Total training steps: 500
Initializing model...
Loading meta-llama/Llama-3.2-8B-Instruct...
Traceback (most recent call last):
  File "/data/miniforge3/lib/python3.10/site-packages/huggingface_hub/utils/_http.py", line 409, in hf_raise_for_status
    response.raise_for_status()
  File "/data/miniforge3/lib/python3.10/site-packages/requests/models.py", line 1026, in raise_for_status
    raise HTTPError(http_error_msg, response=self)
requests.exceptions.HTTPError: 404 Client Error: Not Found for url: https://huggingface.co/meta-llama/Llama-3.2-8B-Instruct/resolve/main/tokenizer_config.json

The above exception was the direct cause of the following exception:

Traceback (most recent call last):
  File "/data/miniforge3/lib/python3.10/site-packages/transformers/utils/hub.py", line 479, in cached_files
    hf_hub_download(
  File "/data/miniforge3/lib/python3.10/site-packages/huggingface_hub/utils/_validators.py", line 114, in _inner_fn
    return fn(*args, **kwargs)
  File "/data/miniforge3/lib/python3.10/site-packages/huggingface_hub/file_download.py", line 1010, in hf_hub_download
    return _hf_hub_download_to_cache_dir(
  File "/data/miniforge3/lib/python3.10/site-packages/huggingface_hub/file_download.py", line 1117, in _hf_hub_download_to_cache_dir
    _raise_on_head_call_error(head_call_error, force_download, local_files_only)
  File "/data/miniforge3/lib/python3.10/site-packages/huggingface_hub/file_download.py", line 1658, in _raise_on_head_call_error
    raise head_call_error
  File "/data/miniforge3/lib/python3.10/site-packages/huggingface_hub/file_download.py", line 1546, in _get_metadata_or_catch_error
    metadata = get_hf_file_metadata(
  File "/data/miniforge3/lib/python3.10/site-packages/huggingface_hub/utils/_validators.py", line 114, in _inner_fn
    return fn(*args, **kwargs)
  File "/data/miniforge3/lib/python3.10/site-packages/huggingface_hub/file_download.py", line 1463, in get_hf_file_metadata
    r = _request_wrapper(
  File "/data/miniforge3/lib/python3.10/site-packages/huggingface_hub/file_download.py", line 286, in _request_wrapper
    response = _request_wrapper(
  File "/data/miniforge3/lib/python3.10/site-packages/huggingface_hub/file_download.py", line 310, in _request_wrapper
    hf_raise_for_status(response)
  File "/data/miniforge3/lib/python3.10/site-packages/huggingface_hub/utils/_http.py", line 459, in hf_raise_for_status
    raise _format(RepositoryNotFoundError, message, response) from e
huggingface_hub.errors.RepositoryNotFoundError: 404 Client Error. (Request ID: Root=1-68e91b41-5c89a68077e28a384a089bec;845a23b6-160a-4fdf-968a-c9da74952b72)

Repository Not Found for url: https://huggingface.co/meta-llama/Llama-3.2-8B-Instruct/resolve/main/tokenizer_config.json.
Please make sure you specified the correct `repo_id` and `repo_type`.
If you are trying to access a private or gated repo, make sure you are authenticated. For more details, see https://huggingface.co/docs/huggingface_hub/authentication

The above exception was the direct cause of the following exception:

Traceback (most recent call last):
  File "/home/ubuntu/TinyRecursiveModels/gpt-integration/training/train_trm_hybrid.py", line 406, in <module>
    main()
  File "/home/ubuntu/TinyRecursiveModels/gpt-integration/training/train_trm_hybrid.py", line 402, in main
    train(config)
  File "/home/ubuntu/TinyRecursiveModels/gpt-integration/training/train_trm_hybrid.py", line 254, in train
    model = HybridTRMModel(model_config).to(config.device)
  File "/home/ubuntu/TinyRecursiveModels/gpt-integration/models/trm_hybrid.py", line 277, in __init__
    self.text_module = TextReasoningModule(
  File "/home/ubuntu/TinyRecursiveModels/gpt-integration/models/text_reasoning.py", line 30, in __init__
    self.tokenizer = AutoTokenizer.from_pretrained(model_name)
  File "/data/miniforge3/lib/python3.10/site-packages/transformers/models/auto/tokenization_auto.py", line 1049, in from_pretrained
    tokenizer_config = get_tokenizer_config(pretrained_model_name_or_path, **kwargs)
  File "/data/miniforge3/lib/python3.10/site-packages/transformers/models/auto/tokenization_auto.py", line 881, in get_tokenizer_config
    resolved_config_file = cached_file(
  File "/data/miniforge3/lib/python3.10/site-packages/transformers/utils/hub.py", line 321, in cached_file
    file = cached_files(path_or_repo_id=path_or_repo_id, filenames=[filename], **kwargs)
  File "/data/miniforge3/lib/python3.10/site-packages/transformers/utils/hub.py", line 511, in cached_files
    raise OSError(
OSError: meta-llama/Llama-3.2-8B-Instruct is not a local folder and is not a valid model identifier listed on 'https://huggingface.co/models'
If this is a private repository, make sure to pass a token having permission to this repo either by logging in with `hf auth login` or by passing `token=<your_token>`
